[2025-03-10 22:40:38,918] INFO - Starting trading bot...
[2025-03-10 22:40:47,561] INFO - Signal: SELL -> Execute sell order
[2025-03-10 22:41:47,653] INFO - Signal: SELL -> Execute sell order
[2025-03-10 22:42:47,730] INFO - Signal: SELL -> Execute sell order
[2025-03-10 22:43:47,835] INFO - Signal: SELL -> Execute sell order
[2025-03-10 22:44:47,921] INFO - Signal: SELL -> Execute sell order
[2025-03-10 22:45:48,002] INFO - Signal: SELL -> Execute sell order
[2025-03-10 22:46:48,087] INFO - Signal: SELL -> Execute sell order
[2025-03-10 23:02:52,211] INFO - Starting trading bot...
[2025-03-10 23:02:53,035] INFO - Signal: SELL -> Execute sell order
[2025-03-10 23:03:53,121] INFO - Signal: SELL -> Execute sell order
[2025-03-10 23:04:53,240] INFO - Signal: SELL -> Execute sell order
[2025-03-10 23:05:53,516] INFO - Signal: SELL -> Execute sell order
[2025-03-10 23:06:53,607] INFO - Signal: SELL -> Execute sell order
[2025-03-10 23:07:53,699] INFO - Signal: SELL -> Execute sell order
[2025-03-10 23:08:55,079] INFO - Starting trading bot...
[2025-03-10 23:08:55,906] INFO - Signal: SELL -> Execute sell order
[2025-03-10 23:09:56,214] INFO - Signal: SELL -> Execute sell order
[2025-03-10 23:10:56,526] INFO - Signal: SELL -> Execute sell order
[2025-03-10 23:11:56,753] INFO - Signal: SELL -> Execute sell order
[2025-03-10 23:12:57,004] INFO - Signal: SELL -> Execute sell order
[2025-03-11 06:28:42,929] ERROR - Error in main loop: binanceusdm {"code":-2008,"msg":"Invalid Api-Key ID."}
Traceback (most recent call last):
  File "/Users/choiwangyu/crypto-bot/venv/lib/python3.10/site-packages/ccxt/base/exchange.py", line 573, in fetch
    response.raise_for_status()
  File "/Users/choiwangyu/crypto-bot/venv/lib/python3.10/site-packages/requests/models.py", line 1024, in raise_for_status
    raise HTTPError(http_error_msg, response=self)
requests.exceptions.HTTPError: 400 Client Error:  for url: https://api.binance.com/sapi/v1/capital/config/getall?timestamp=1741642122834&recvWindow=10000&signature=cbf82a077df0963ce194e1f50ce045123f5759a684b0654a8f6f966cb18f099b

During handling of the above exception, another exception occurred:

Traceback (most recent call last):
  File "/Users/choiwangyu/crypto-bot/src/main.py", line 17, in main
    df = fetch_ohlcv_data(exchange, DEFAULT_SYMBOL, DEFAULT_TIMEFRAME, limit=50)
  File "/Users/choiwangyu/crypto-bot/src/data_collector.py", line 27, in fetch_ohlcv_data
    ohlcv = exchange.fetch_ohlcv(symbol, timeframe=timeframe, limit=limit)
  File "/Users/choiwangyu/crypto-bot/venv/lib/python3.10/site-packages/ccxt/binance.py", line 4626, in fetch_ohlcv
    self.load_markets()
  File "/Users/choiwangyu/crypto-bot/venv/lib/python3.10/site-packages/ccxt/base/exchange.py", line 1508, in load_markets
    currencies = self.fetch_currencies()
  File "/Users/choiwangyu/crypto-bot/venv/lib/python3.10/site-packages/ccxt/binance.py", line 2992, in fetch_currencies
    promises = [self.sapiGetCapitalConfigGetall(params)]
  File "/Users/choiwangyu/crypto-bot/venv/lib/python3.10/site-packages/ccxt/base/types.py", line 35, in unbound_method
    return _self.request(self.path, self.api, self.method, params, config=self.config)
  File "/Users/choiwangyu/crypto-bot/venv/lib/python3.10/site-packages/ccxt/binance.py", line 11483, in request
    response = self.fetch2(path, api, method, params, headers, body, config)
  File "/Users/choiwangyu/crypto-bot/venv/lib/python3.10/site-packages/ccxt/base/exchange.py", line 4355, in fetch2
    raise e
  File "/Users/choiwangyu/crypto-bot/venv/lib/python3.10/site-packages/ccxt/base/exchange.py", line 4345, in fetch2
    return self.fetch(request['url'], request['method'], request['headers'], request['body'])
  File "/Users/choiwangyu/crypto-bot/venv/lib/python3.10/site-packages/ccxt/base/exchange.py", line 589, in fetch
    skip_further_error_handling = self.handle_errors(http_status_code, http_status_text, url, method, headers, http_response, json_response, request_headers, request_body)
  File "/Users/choiwangyu/crypto-bot/venv/lib/python3.10/site-packages/ccxt/binance.py", line 11450, in handle_errors
    self.throw_exactly_matched_exception(self.get_exceptions_by_url(url, 'exact'), error, feedback)
  File "/Users/choiwangyu/crypto-bot/venv/lib/python3.10/site-packages/ccxt/base/exchange.py", line 4748, in throw_exactly_matched_exception
    raise exact[string](message)
ccxt.base.errors.AuthenticationError: binanceusdm {"code":-2008,"msg":"Invalid Api-Key ID."}
[2025-03-11 07:00:32,752] ERROR - Error in main loop: binanceusdm {"code":-2008,"msg":"Invalid Api-Key ID."}
Traceback (most recent call last):
  File "/Users/choiwangyu/crypto-bot/venv/lib/python3.10/site-packages/ccxt/base/exchange.py", line 573, in fetch
    response.raise_for_status()
  File "/Users/choiwangyu/crypto-bot/venv/lib/python3.10/site-packages/requests/models.py", line 1024, in raise_for_status
    raise HTTPError(http_error_msg, response=self)
requests.exceptions.HTTPError: 400 Client Error:  for url: https://api.binance.com/sapi/v1/capital/config/getall?timestamp=1741644032657&recvWindow=10000&signature=02e93f261ec07980b98caf603e3f811a5e82d5e365232f3142368ac332dd9c14

During handling of the above exception, another exception occurred:

Traceback (most recent call last):
  File "/Users/choiwangyu/crypto-bot/src/main.py", line 17, in main
    df = fetch_ohlcv_data(exchange, DEFAULT_SYMBOL, DEFAULT_TIMEFRAME, limit=50)
  File "/Users/choiwangyu/crypto-bot/src/data_collector.py", line 27, in fetch_ohlcv_data
    ohlcv = exchange.fetch_ohlcv(symbol, timeframe=timeframe, limit=limit)
  File "/Users/choiwangyu/crypto-bot/venv/lib/python3.10/site-packages/ccxt/binance.py", line 4626, in fetch_ohlcv
    self.load_markets()
  File "/Users/choiwangyu/crypto-bot/venv/lib/python3.10/site-packages/ccxt/base/exchange.py", line 1508, in load_markets
    currencies = self.fetch_currencies()
  File "/Users/choiwangyu/crypto-bot/venv/lib/python3.10/site-packages/ccxt/binance.py", line 2992, in fetch_currencies
    promises = [self.sapiGetCapitalConfigGetall(params)]
  File "/Users/choiwangyu/crypto-bot/venv/lib/python3.10/site-packages/ccxt/base/types.py", line 35, in unbound_method
    return _self.request(self.path, self.api, self.method, params, config=self.config)
  File "/Users/choiwangyu/crypto-bot/venv/lib/python3.10/site-packages/ccxt/binance.py", line 11483, in request
    response = self.fetch2(path, api, method, params, headers, body, config)
  File "/Users/choiwangyu/crypto-bot/venv/lib/python3.10/site-packages/ccxt/base/exchange.py", line 4355, in fetch2
    raise e
  File "/Users/choiwangyu/crypto-bot/venv/lib/python3.10/site-packages/ccxt/base/exchange.py", line 4345, in fetch2
    return self.fetch(request['url'], request['method'], request['headers'], request['body'])
  File "/Users/choiwangyu/crypto-bot/venv/lib/python3.10/site-packages/ccxt/base/exchange.py", line 589, in fetch
    skip_further_error_handling = self.handle_errors(http_status_code, http_status_text, url, method, headers, http_response, json_response, request_headers, request_body)
  File "/Users/choiwangyu/crypto-bot/venv/lib/python3.10/site-packages/ccxt/binance.py", line 11450, in handle_errors
    self.throw_exactly_matched_exception(self.get_exceptions_by_url(url, 'exact'), error, feedback)
  File "/Users/choiwangyu/crypto-bot/venv/lib/python3.10/site-packages/ccxt/base/exchange.py", line 4748, in throw_exactly_matched_exception
    raise exact[string](message)
ccxt.base.errors.AuthenticationError: binanceusdm {"code":-2008,"msg":"Invalid Api-Key ID."}
[2025-03-11 07:01:32,831] ERROR - Error in main loop: binanceusdm {"code":-2008,"msg":"Invalid Api-Key ID."}
Traceback (most recent call last):
  File "/Users/choiwangyu/crypto-bot/venv/lib/python3.10/site-packages/ccxt/base/exchange.py", line 573, in fetch
    response.raise_for_status()
  File "/Users/choiwangyu/crypto-bot/venv/lib/python3.10/site-packages/requests/models.py", line 1024, in raise_for_status
    raise HTTPError(http_error_msg, response=self)
requests.exceptions.HTTPError: 400 Client Error:  for url: https://api.binance.com/sapi/v1/capital/config/getall?timestamp=1741644092766&recvWindow=10000&signature=3a1544e1879269bc57c9c737b293c262f1dc35fdb23617bb07105fada45bb4f2

During handling of the above exception, another exception occurred:

Traceback (most recent call last):
  File "/Users/choiwangyu/crypto-bot/src/main.py", line 17, in main
    df = fetch_ohlcv_data(exchange, DEFAULT_SYMBOL, DEFAULT_TIMEFRAME, limit=50)
  File "/Users/choiwangyu/crypto-bot/src/data_collector.py", line 27, in fetch_ohlcv_data
    ohlcv = exchange.fetch_ohlcv(symbol, timeframe=timeframe, limit=limit)
  File "/Users/choiwangyu/crypto-bot/venv/lib/python3.10/site-packages/ccxt/binance.py", line 4626, in fetch_ohlcv
    self.load_markets()
  File "/Users/choiwangyu/crypto-bot/venv/lib/python3.10/site-packages/ccxt/base/exchange.py", line 1508, in load_markets
    currencies = self.fetch_currencies()
  File "/Users/choiwangyu/crypto-bot/venv/lib/python3.10/site-packages/ccxt/binance.py", line 2992, in fetch_currencies
    promises = [self.sapiGetCapitalConfigGetall(params)]
  File "/Users/choiwangyu/crypto-bot/venv/lib/python3.10/site-packages/ccxt/base/types.py", line 35, in unbound_method
    return _self.request(self.path, self.api, self.method, params, config=self.config)
  File "/Users/choiwangyu/crypto-bot/venv/lib/python3.10/site-packages/ccxt/binance.py", line 11483, in request
    response = self.fetch2(path, api, method, params, headers, body, config)
  File "/Users/choiwangyu/crypto-bot/venv/lib/python3.10/site-packages/ccxt/base/exchange.py", line 4355, in fetch2
    raise e
  File "/Users/choiwangyu/crypto-bot/venv/lib/python3.10/site-packages/ccxt/base/exchange.py", line 4345, in fetch2
    return self.fetch(request['url'], request['method'], request['headers'], request['body'])
  File "/Users/choiwangyu/crypto-bot/venv/lib/python3.10/site-packages/ccxt/base/exchange.py", line 589, in fetch
    skip_further_error_handling = self.handle_errors(http_status_code, http_status_text, url, method, headers, http_response, json_response, request_headers, request_body)
  File "/Users/choiwangyu/crypto-bot/venv/lib/python3.10/site-packages/ccxt/binance.py", line 11450, in handle_errors
    self.throw_exactly_matched_exception(self.get_exceptions_by_url(url, 'exact'), error, feedback)
  File "/Users/choiwangyu/crypto-bot/venv/lib/python3.10/site-packages/ccxt/base/exchange.py", line 4748, in throw_exactly_matched_exception
    raise exact[string](message)
ccxt.base.errors.AuthenticationError: binanceusdm {"code":-2008,"msg":"Invalid Api-Key ID."}
[2025-03-11 07:02:09,204] ERROR - Error in main loop: NDFrame.rolling() got an unexpected keyword argument 'term'
Traceback (most recent call last):
  File "/Users/choiwangyu/crypto-bot/src/main.py", line 30, in main
    signal = generate_signal(df)
  File "/Users/choiwangyu/crypto-bot/src/strategy.py", line 13, in generate_signal
    df['ma_short'] = df['close'].rolling(term = short_term).mean()
TypeError: NDFrame.rolling() got an unexpected keyword argument 'term'
[2025-03-11 07:03:09,276] ERROR - Error in main loop: NDFrame.rolling() got an unexpected keyword argument 'term'
Traceback (most recent call last):
  File "/Users/choiwangyu/crypto-bot/src/main.py", line 30, in main
    signal = generate_signal(df)
  File "/Users/choiwangyu/crypto-bot/src/strategy.py", line 13, in generate_signal
    df['ma_short'] = df['close'].rolling(term = short_term).mean()
TypeError: NDFrame.rolling() got an unexpected keyword argument 'term'
[2025-03-11 07:03:45,384] INFO - Signal: hold, last_price=79265.3
[2025-03-11 07:04:42,416] INFO - Signal: hold, last_price=79567.4
[2025-03-11 07:05:42,538] INFO - Signal: hold, last_price=79405.6
[2025-03-11 07:06:42,621] INFO - Signal: hold, last_price=79573.6
[2025-03-11 07:07:42,709] INFO - Signal: hold, last_price=79573.6
